Workbook

Sheet Liquidity Ladder
A1: # Project 1 Part A: Transaction Cost Modeling Exercise
A2: Part 1: Build the Liquidity Ladder
A3: Level | B3: Frac of ADV | C3: Market Impact (bps) | D3: Cumulative Frac of ADV | E3: Cumulative Impact (bps) | F3: Cost = a × (Frac)^b | G3: SE | H3: Cost = a × / (Frac) + b | I3: SE | J3: a + b×ln(x) | K3: SE
A4: 1 | B4: =0.001 * 2^(A4-1) -> 0.001 | C4: =1 + (A4-1) * 41 -> 1 | D4: =SUM($B$4:B4) -> 0.001 | E4: =SUMPRODUCT($B$4:B4,$C$4:C4)/D4 -> 1 | F4: =$C$16*(D4^$C$17) -> 40.75584 | G4: =(E4-F4)^2 -> 1580.5268 | H4: =$E$16*SQRT(D4)+$E$17 -> 31.380357 | I4: =(E4-H4)^2 -> 922.96611 | J4: =$H$16+$H$17*LN(D4) -> -25.792616 | K4: =(E4-J4)^2 -> 717.84429
A5: 2 | B5: =0.001 * 2^(A5-1) -> 0.002 | C5: 41 | D5: =SUM($B$4:B5) -> 0.003 | E5: =SUMPRODUCT($B$4:B5,$C$4:C5)/D5 -> 27.666667 | F5: =$C$16*(D5^$C$17) -> 57.393877 | G5: =(E5-F5)^2 -> 883.70703 | H5: =$E$16*SQRT(D5)+$E$17 -> 43.259798 | I5: =(E5-H5)^2 -> 243.14576 | J5: =$H$16+$H$17*LN(D5) -> 28.019672 | K5: =(E5-J5)^2 -> 0.12461296
A6: 3 | B6: =0.001 * 2^(A6-1) -> 0.004 | C6: =C5+41 -> 82 | D6: =SUM($B$4:B6) -> 0.007 | E6: =SUMPRODUCT($B$4:B6,$C$4:C6)/D6 -> 58.714286 | F6: =$C$16*(D6^$C$17) -> 74.73616 | G6: =(E6-F6)^2 -> 256.70045 | H6: =$E$16*SQRT(D6)+$E$17 -> 58.086981 | I6: =(E6-H6)^2 -> 0.39351083 | J6: =$H$16+$H$17*LN(D6) -> 69.522063 | K6: =(E6-J6)^2 -> 116.80806
A7: 4 | B7: =0.001 * 2^(A7-1) -> 0.008 | C7: =C6+41 -> 123 | D7: =SUM($B$4:B7) -> 0.015 | E7: =SUMPRODUCT($B$4:B7,$C$4:C7)/D7 -> 93 | F7: =$C$16*(D7^$C$17) -> 94.770146 | G7: =(E7-F7)^2 -> 3.133418 | H7: =$E$16*SQRT(D7)+$E$17 -> 78.002034 | I7: =(E7-H7)^2 -> 224.93898 | J7: =$H$16+$H$17*LN(D7) -> 106.85325 | K7: =(E7-J7)^2 -> 191.91254
A8: 5 | B8: =0.001 * 2^(A8-1) -> 0.016 | C8: =C7+41 -> 164 | D8: =SUM($B$4:B8) -> 0.031 | E8: =SUMPRODUCT($B$4:B8,$C$4:C8)/D8 -> 129.64516 | F8: =$C$16*(D8^$C$17) -> 118.8264 | G8: =(E8-F8)^2 -> 117.04555 | H8: =$E$16*SQRT(D8)+$E$17 -> 105.50429 | I8: =(E8-H8)^2 -> 582.78149 | J8: =$H$16+$H$17*LN(D8) -> 142.41114 | K8: =(E8-J8)^2 -> 162.97013
A9: 6 | B9: =0.001 * 2^(A9-1) -> 0.032 | C9: =C8+41 -> 205 | D9: =SUM($B$4:B9) -> 0.063 | E9: =SUMPRODUCT($B$4:B9,$C$4:C9)/D9 -> 167.92063 | F9: =$C$16*(D9^$C$17) -> 148.21161 | G9: =(E9-F9)^2 -> 388.4458 | H9: =$E$16*SQRT(D9)+$E$17 -> 143.95547 | I9: =(E9-H9)^2 -> 574.32933 | J9: =$H$16+$H$17*LN(D9) -> 177.14664 | K9: =(E9-J9)^2 -> 85.119179
A10: 7 | B10: =0.001 * 2^(A10-1) -> 0.064 | C10: =C9+41 -> 246 | D10: =SUM($B$4:B10) -> 0.127 | E10: =SUMPRODUCT($B$4:B10,$C$4:C10)/D10 -> 207.26772 | F10: =$C$16*(D10^$C$17) -> 184.3979 | G10: =(E10-F10)^2 -> 523.02871 | H10: =$E$16*SQRT(D10)+$E$17 -> 198.02871 | I10: =(E10-H10)^2 -> 85.359259 | J10: =$H$16+$H$17*LN(D10) -> 211.48563 | K10: =(E10-J10)^2 -> 17.790764
A11: 8 | B11: =0.001 * 2^(A11-1) -> 0.128 | C11: =C10+41 -> 287 | D11: =SUM($B$4:B11) -> 0.255 | E11: =SUMPRODUCT($B$4:B11,$C$4:C11)/D11 -> 247.2902 | F11: =$C$16*(D11^$C$17) -> 229.13511 | G11: =(E11-F11)^2 -> 329.60705 | H11: =$E$16*SQRT(D11)+$E$17 -> 274.28702 | I11: =(E11-H11)^2 -> 728.82859 | J11: =$H$16+$H$17*LN(D11) -> 245.62986 | K11: =(E11-J11)^2 -> 2.7567011
A12: 9 | B12: =0.001 * 2^(A12-1) -> 0.256 | C12: =C11+41 -> 328 | D12: =SUM($B$4:B12) -> 0.511 | E12: =SUMPRODUCT($B$4:B12,$C$4:C12)/D12 -> 287.72407 | F12: =$C$16*(D12^$C$17) -> 284.55137 | G12: =(E12-F12)^2 -> 10.066058 | H12: =$E$16*SQRT(D12)+$E$17 -> 381.98307 | I12: =(E12-H12)^2 -> 8884.7581 | J12: =$H$16+$H$17*LN(D12) -> 279.67759 | K12: =(E12-J12)^2 -> 64.745886
A13: 10 | B13: =0.001 * 2^(A13-1) -> 0.512 | C13: =C12+41 -> 369 | D13: =SUM($B$4:B13) -> 1.023 | E13: =SUMPRODUCT($B$4:B13,$C$4:C13)/D13 -> 328.40176 | F13: =$C$16*(D13^$C$17) -> 353.26203 | G13: =(E13-F13)^2 -> 618.03304 | H13: =$E$16*SQRT(D13)+$E$17 -> 534.1829 | I13: =(E13-H13)^2 -> 42345.88 | J13: =$H$16+$H$17*LN(D13) -> 313.67727 | K13: =(E13-J13)^2 -> 216.81072
B16: a | C16: 350.76772 | D16: a | E16: 513.16235 | G16: a | H16: 312.56344
B17: b | C17: 0.31160992 | D17: b | E17: 15.152739 | G17: b | H17: 48.982056
B18: SSE | C18: =SUM(G4:G13) -> 4710.2939 | D18: SSE | E18: =SUM(I4:I11) -> 3362.743 | G18: SSE | H18: =SUM(K4:K13) -> 1576.8829
A21: Part 2: Visualize the Cost Curve
A22: Create Two Scatter Plots
A40: Analysis Questions
A41: 1 | B41: Shape Analysis: Describe the curve shape on the original scale. Is it linear? Where does cost accelerate noticeably?
B42: The curve shape on the original scale is non-linear and concave. It rises quickly at first and then gradually flattens out as it increases, meaning that this isn't linear. The cost accelerates noticeably as the cumulative impact moves from 0 to 0.2, and starts flatenning out after that, meaning the marginal cost of additional trades become higher.
A43: 2 | B43: Log Scale Comparison: How does the curve look different on a log scale? Which visualization makes it easier to see the behavior at small trade sizes (0–1% ADV) vs large trade sizes? Which plot would you show a portfolio manager and why?
B44: The curve looks different on a log scale graph because it looks rather like a straight linear line and the points are more evenly spread out compared to the original scale. On the original scale, the curve rises quickly at first and then gradually flattens out as it increases. The log scale makes smaller trade sizes easier to see, while the original scale shows how costs increase more sharply as trade size increases. I would show a portfolio manager the original scale plot because it highlights how transaction costs accelerate as trade size increases, which is important for managing risk.
A45: 3 | B45: Functional Form Hypothesis: Based on the visual shape, what type of function might fit? Consider: power law (x^b), square root (√x), logarithmic (ln(x)). Which makes economic sense for liquidity exhaustion?
B46: Based on the visual shape, the function that might be the best fit is the logarithmic (ln(x)). The yellow logarithmic curve closely overlaps with the blue original curve. The logarithmic (ln(x)) function also makes the most economic sense for liquidity exhaustion, as each additional share costs more than the previous one.
A48: Part 3: Fit Mathematical Models
A50: Comparison Table
A51: Model | B51: Formula | C51: a | D51: b | E51: SSE | F51: R^2
A52: Power Law | B52: a×x^b | C52: =C16 -> 350.76772 | D52: =C17 -> 0.31160992 | E52: =C18 -> 4710.2939 | F52: {=1-(E52/(SUMPRODUCT((E4:E13 - AVERAGE(E4:E13))^2)))} -> 0.95823748
A53: Square Root | B53: a×√x + b | C53: =E16 -> 513.16235 | D53: =E17 -> 15.152739 | E53: =E18 -> 3362.743 | F53: {=1-(E53/(SUMPRODUCT((E4:E13 - AVERAGE(E4:E13))^2)))} -> 0.97018517
A54: Logarithmic | B54: a + b×ln(x) | C54: =H16 -> 312.56344 | D54: =H17 -> 48.982056 | E54: =H18 -> 1576.8829 | F54: {=1-(E54/(SUMPRODUCT((E4:E13 - AVERAGE(E4:E13))^2)))} -> 0.986019
A57: Part 4: Model Selection & Application
A58: 1 | B58: Best Fit: Which model has lowest SSE and highest R²? Does it make economic sense?
B59: The logarithmic model has the lowest SSE (≈1577), meaning it fits the cumulative impact curve best. The square‑root model is the next closest, and the power‑law model performs worst. While the logarithmic model offers a superior statistical fit, it fails the economic reality test because its negative intercept predicts impossible price improvements for small trades rather than reflecting the positive, concave rise in cost as liquidity is exhausted.
A61: 2 | B61: Parameter Interpretation: For your best model, what do the parameters a and b mean economically?
B62: a = 312.56. This represents the intercept, the impact we would get as x approches ADV.
B63: b = 48.98. This controls the impact as trade size grows. A and B positive means impact rises as you trade larger fractions of ADV.
A65: 3 | B65: Practical Calculation: Using your best-fit formula, calculate market impact for
C66: Calculated Market Impact | D66: Actual Value | E66: Error | F66: How close?
B67: 0.5% of ADV | C67: =C54+D54*LN(0.005) -> 53.040962 | D67: =E5+((0.005-0.003)/(0.007-0.003))*(E6-E5) -> 43.190476 | E67: =C67-D67 -> 9.8504853 | F67: Slightly higher than the actual value
...

Sheet Model A UB (Nonlinear)
A1: Symbol | B1: Fund Name | C1: Stock Price | D1: AUM | E1: Expense Ratio | F1: Beta | G1: Dollar Volume | H1: Tech | I1: Expected Return | J1: Investment | K1: Frac ADV | L1: Tcosts | M1: Exp Profit | Q1: Just for Reference | S1: Part 2: Model Setup — Key Assumptions
A2: TQQQ | B2: ProShares UltraPro QQQ | C2: 48.26 | D2: 28.70B | E2: 0.0082 | F2: 3.58 | G2: =IF(RIGHT(Q2,1)="B", VALUE(SUBSTITUTE(Q2,"B",""))*1000000000, IF(RIGHT(Q2,1)="M", VALUE(SUBSTITUTE(Q2,"M",""))*1000000, VALUE(Q2))) -> 5570000000 | H2: =OR( ISNUMBER(SEARCH("technology",B2)), ISNUMBER(SEARCH("tech",B2)), ISNUMBER(SEARCH("qqq",B2)), ISNUMBER(SEARCH("semiconductor",B2)), ISNUMBER(SEARCH("information technology",B2)), ISNUMBER(SEARCH("nasdaq",B2)), ISNUMBER(SEARCH("communication",B2)) ) -> TRUE | I2: =Table1[[#This Row],[Tech]]*$T$7+Table1[[#This Row],[Beta]]*($T$6-$T$8)+$T$8 -> 0.364088 | J2: 6.9073603e+08 | K2: =Table1[[#This Row],[Investment]]/Table1[[#This Row],[Dollar Volume]] -> 0.12401006 | L2: =IFERROR(MAX($T$11+$T$12*LN(Table1[[#This Row],[Frac ADV]]),0),0)*0.0001+0.005/Table1[[#This Row],[Stock Price]]+Table1[[#This Row],[Expense Ratio]] -> 0.029335471 | M2: =(Table1[[#This Row],[Expected Return]]-Table1[[#This Row],[Tcosts]])*Table1[[#This Row],[Investment]] -> 2.3122563e+08 | Q2: 5.57B
A3: SMH | B3: VanEck Semiconductor ETF | C3: 406.11 | D3: 45.17B | E3: 0.0035 | F3: 1.71 | G3: =IF(RIGHT(Q3,1)="B", VALUE(SUBSTITUTE(Q3,"B",""))*1000000000, IF(RIGHT(Q3,1)="M", VALUE(SUBSTITUTE(Q3,"M",""))*1000000, VALUE(Q3))) -> 5500000000 | H3: =OR( ISNUMBER(SEARCH("technology",B3)), ISNUMBER(SEARCH("tech",B3)), ISNUMBER(SEARCH("qqq",B3)), ISNUMBER(SEARCH("semiconductor",B3)), ISNUMBER(SEARCH("information technology",B3)), ISNUMBER(SEARCH("nasdaq",B3)), ISNUMBER(SEARCH("communication",B3)) ) -> TRUE | I3: =Table1[[#This Row],[Tech]]*$T$7+Table1[[#This Row],[Beta]]*($T$6-$T$8)+$T$8 -> 0.245156 | J3: 4.1410526e+08 | K3: =Table1[[#This Row],[Investment]]/Table1[[#This Row],[Dollar Volume]] -> 0.075291865 | L3: =IFERROR(MAX($T$11+$T$12*LN(Table1[[#This Row],[Frac ADV]]),0),0)*0.0001+0.005/Table1[[#This Row],[Stock Price]]+Table1[[#This Row],[Expense Ratio]] -> 0.022100019 | M3: =(Table1[[#This Row],[Expected Return]]-Table1[[#This Row],[Tcosts]])*Table1[[#This Row],[Investment]] -> 92368654 | Q3: 5.50B | S3: Assumptions
A4: SOXX | B4: iShares Semiconductor ETF | C4: 351.5 | D4: 22.09B | E4: 0.0034 | F4: 1.74 | G4: =IF(RIGHT(Q4,1)="B", VALUE(SUBSTITUTE(Q4,"B",""))*1000000000, IF(RIGHT(Q4,1)="M", VALUE(SUBSTITUTE(Q4,"M",""))*1000000, VALUE(Q4))) -> 79900000000 | H4: =OR( ISNUMBER(SEARCH("technology",B4)), ISNUMBER(SEARCH("tech",B4)), ISNUMBER(SEARCH("qqq",B4)), ISNUMBER(SEARCH("semiconductor",B4)), ISNUMBER(SEARCH("information technology",B4)), ISNUMBER(SEARCH("nasdaq",B4)), ISNUMBER(SEARCH("communication",B4)) ) -> TRUE | I4: =Table1[[#This Row],[Tech]]*$T$7+Table1[[#This Row],[Beta]]*($T$6-$T$8)+$T$8 -> 0.247064 | J4: 4.0595474e+08 | K4: =Table1[[#This Row],[Investment]]/Table1[[#This Row],[Dollar Volume]] -> 0.0050807852 | L4: =IFERROR(MAX($T$11+$T$12*LN(Table1[[#This Row],[Frac ADV]]),0),0)*0.0001+0.005/Table1[[#This Row],[Stock Price]]+Table1[[#This Row],[Expense Ratio]] -> 0.0087968289 | M4: =(Table1[[#This Row],[Expected Return]]-Table1[[#This Row],[Tcosts]])*Table1[[#This Row],[Investment]] -> 96725687 | Q4: 79.90B | S4: Parameter | T4: Value | U4: Notes
A5: SOXL | B5: Direxion Daily Semiconductor Bull 3x Shares | C5: 63.1 | D5: 13.17B | E5: 0.0075 | F5: =4.99/3 -> 1.6633333 | G5: =IF(RIGHT(Q5,1)="B", VALUE(SUBSTITUTE(Q5,"B",""))*1000000000, IF(RIGHT(Q5,1)="M", VALUE(SUBSTITUTE(Q5,"M",""))*1000000, VALUE(Q5))) -> 2350000000 | H5: =OR( ISNUMBER(SEARCH("technology",B5)), ISNUMBER(SEARCH("tech",B5)), ISNUMBER(SEARCH("qqq",B5)), ISNUMBER(SEARCH("semiconductor",B5)), ISNUMBER(SEARCH("information technology",B5)), ISNUMBER(SEARCH("nasdaq",B5)), ISNUMBER(SEARCH("communication",B5)) ) -> TRUE | I5: =Table1[[#This Row],[Tech]]*$T$7+Table1[[#This Row],[Beta]]*($T$6-$T$8)+$T$8 -> 0.242188 | J5: 3.6625667e+08 | K5: =Table1[[#This Row],[Investment]]/Table1[[#This Row],[Dollar Volume]] -> 0.1558539 | L5: =IFERROR(MAX($T$11+$T$12*LN(Table1[[#This Row],[Frac ADV]]),0),0)*0.0001+0.005/Table1[[#This Row],[Stock Price]]+Table1[[#This Row],[Expense Ratio]] -> 0.029730621 | M5: =(Table1[[#This Row],[Expected Return]]-Table1[[#This Row],[Tcosts]])*Table1[[#This Row],[Investment]] -> 77813932 | Q5: 2.35B | S5: Starting Capital | T5: 1000000000 | U5: Fund equity
A6: FTEC | B6: Fidelity MSCI Information Technology Index ETF | C6: 217.72 | D6: 16.24B | E6: 0.0008 | F6: 1.43 | G6: =IF(RIGHT(Q6,1)="B", VALUE(SUBSTITUTE(Q6,"B",""))*1000000000, IF(RIGHT(Q6,1)="M", VALUE(SUBSTITUTE(Q6,"M",""))*1000000, VALUE(Q6))) -> 48350000000 | H6: =OR( ISNUMBER(SEARCH("technology",B6)), ISNUMBER(SEARCH("tech",B6)), ISNUMBER(SEARCH("qqq",B6)), ISNUMBER(SEARCH("semiconductor",B6)), ISNUMBER(SEARCH("information technology",B6)), ISNUMBER(SEARCH("nasdaq",B6)), ISNUMBER(SEARCH("communication",B6)) ) -> TRUE | I6: =Table1[[#This Row],[Tech]]*$T$7+Table1[[#This Row],[Beta]]*($T$6-$T$8)+$T$8 -> 0.227348 | J6: 3.6016014e+08 | K6: =Table1[[#This Row],[Investment]]/Table1[[#This Row],[Dollar Volume]] -> 0.0074490205 | L6: =IFERROR(MAX($T$11+$T$12*LN(Table1[[#This Row],[Frac ADV]]),0),0)*0.0001+0.005/Table1[[#This Row],[Stock Price]]+Table1[[#This Row],[Expense Ratio]] -> 0.0080797048 | M6: =(Table1[[#This Row],[Expected Return]]-Table1[[#This Row],[Tcosts]])*Table1[[#This Row],[Investment]] -> 78971700 | Q6: 48.35B | S6: Market Return | T6: 0.1 | U6: Expected S&P 500 gain (annual)
A7: VGT | B7: Vanguard Information Technology ETF | C7: 729.64 | D7: 113.34B | E7: 0.0009 | F7: 1.43 | G7: =IF(RIGHT(Q7,1)="B", VALUE(SUBSTITUTE(Q7,"B",""))*1000000000, IF(RIGHT(Q7,1)="M", VALUE(SUBSTITUTE(Q7,"M",""))*1000000, VALUE(Q7))) -> 1360000000 | H7: =OR( ISNUMBER(SEARCH("technology",B7)), ISNUMBER(SEARCH("tech",B7)), ISNUMBER(SEARCH("qqq",B7)), ISNUMBER(SEARCH("semiconductor",B7)), ISNUMBER(SEARCH("information technology",B7)), ISNUMBER(SEARCH("nasdaq",B7)), ISNUMBER(SEARCH("communication",B7)) ) -> TRUE | I7: =Table1[[#This Row],[Tech]]*$T$7+Table1[[#This Row],[Beta]]*($T$6-$T$8)+$T$8 -> 0.227348 | J7: 3.5705911e+08 | K7: =Table1[[#This Row],[Investment]]/Table1[[#This Row],[Dollar Volume]] -> 0.26254347 | L7: =IFERROR(MAX($T$11+$T$12*LN(Table1[[#This Row],[Frac ADV]]),0),0)*0.0001+0.005/Table1[[#This Row],[Stock Price]]+Table1[[#This Row],[Expense Ratio]] -> 0.025612637 | M7: =(Table1[[#This Row],[Expected Return]]-Table1[[#This Row],[Tcosts]])*Table1[[#This Row],[Investment]] -> 72031450 | Q7: 1.36B | S7: Tech Alpha | T7: 0.1 | U7: Additional annual return for tech ETFs
A8: XLK | B8: State Street Technology Select Sector SPDR ETF | C8: 139.21 | D8: 90.52B | E8: 0.0008 | F8: 1.41 | G8: =IF(RIGHT(Q8,1)="B", VALUE(SUBSTITUTE(Q8,"B",""))*1000000000, IF(RIGHT(Q8,1)="M", VALUE(SUBSTITUTE(Q8,"M",""))*1000000, VALUE(Q8))) -> 1020000000 | H8: =OR( ISNUMBER(SEARCH("technology",B8)), ISNUMBER(SEARCH("tech",B8)), ISNUMBER(SEARCH("qqq",B8)), ISNUMBER(SEARCH("semiconductor",B8)), ISNUMBER(SEARCH("information technology",B8)), ISNUMBER(SEARCH("nasdaq",B8)), ISNUMBER(SEARCH("communication",B8)) ) -> TRUE | I8: =Table1[[#This Row],[Tech]]*$T$7+Table1[[#This Row],[Beta]]*($T$6-$T$8)+$T$8 -> 0.226076 | J8: 3.4544057e+08 | K8: =Table1[[#This Row],[Investment]]/Table1[[#This Row],[Dollar Volume]] -> 0.33866723 | L8: =IFERROR(MAX($T$11+$T$12*LN(Table1[[#This Row],[Frac ADV]]),0),0)*0.0001+0.005/Table1[[#This Row],[Stock Price]]+Table1[[#This Row],[Expense Ratio]] -> 0.026788791 | M8: =(Table1[[#This Row],[Expected Return]]-Table1[[#This Row],[Tcosts]])*Table1[[#This Row],[Investment]] -> 68841887 | Q8: 1.02B | S8: Fed Funds Rate | T8: 0.0364 | U8: Look up current rate at Federal Reserve | V8: 46076
A9: IYW | B9: iShares U.S. Technology ETF | C9: 190.79 | D9: 20.42B | E9: 0.0038 | F9: 1.43 | G9: =IF(RIGHT(Q9,1)="B", VALUE(SUBSTITUTE(Q9,"B",""))*1000000000, IF(RIGHT(Q9,1)="M", VALUE(SUBSTITUTE(Q9,"M",""))*1000000, VALUE(Q9))) -> 1800000000 | H9: =OR( ISNUMBER(SEARCH("technology",B9)), ISNUMBER(SEARCH("tech",B9)), ISNUMBER(SEARCH("qqq",B9)), ISNUMBER(SEARCH("semiconductor",B9)), ISNUMBER(SEARCH("information technology",B9)), ISNUMBER(SEARCH("nasdaq",B9)), ISNUMBER(SEARCH("communication",B9)) ) -> TRUE | I9: =Table1[[#This Row],[Tech]]*$T$7+Table1[[#This Row],[Beta]]*($T$6-$T$8)+$T$8 -> 0.227348 | J9: 3.3758993e+08 | K9: =Table1[[#This Row],[Investment]]/Table1[[#This Row],[Dollar Volume]] -> 0.18754996 | L9: =IFERROR(MAX($T$11+$T$12*LN(Table1[[#This Row],[Frac ADV]]),0),0)*0.0001+0.005/Table1[[#This Row],[Stock Price]]+Table1[[#This Row],[Expense Ratio]] -> 0.026884375 | M9: =(Table1[[#This Row],[Expected Return]]-Table1[[#This Row],[Tcosts]])*Table1[[#This Row],[Investment]] -> 67674500 | Q9: 1.80B | S9: Margin Interest Rate | T9: =T8+2% -> 0.0564 | U9: Annual cost of borrowing
A10: QQQ | B10: Invesco QQQ Trust Series I | C10: 600.64 | D10: 402.60B | E10: 0.002 | F10: 1.22 | G10: =IF(RIGHT(Q10,1)="B", VALUE(SUBSTITUTE(Q10,"B",""))*1000000000, IF(RIGHT(Q10,1)="M", VALUE(SUBSTITUTE(Q10,"M",""))*1000000, VALUE(Q10))) -> 9210000000 | H10: =OR( ISNUMBER(SEARCH("technology",B10)), ISNUMBER(SEARCH("tech",B10)), ISNUMBER(SEARCH("qqq",B10)), ISNUMBER(SEARCH("semiconductor",B10)), ISNUMBER(SEARCH("information technology",B10)), ISNUMBER(SEARCH("nasdaq",B10)), ISNUMBER(SEARCH("communication",B10)) ) -> TRUE | I10: =Table1[[#This Row],[Tech]]*$T$7+Table1[[#This Row],[Beta]]*($T$6-$T$8)+$T$8 -> 0.213992 | J10: 3.2620048e+08 | K10: =Table1[[#This Row],[Investment]]/Table1[[#This Row],[Dollar Volume]] -> 0.035418076 | L10: =IFERROR(MAX($T$11+$T$12*LN(Table1[[#This Row],[Frac ADV]]),0),0)*0.0001+0.005/Table1[[#This Row],[Stock Price]]+Table1[[#This Row],[Expense Ratio]] -> 0.016902051 | M10: =(Table1[[#This Row],[Expected Return]]-Table1[[#This Row],[Tcosts]])*Table1[[#This Row],[Investment]] -> 64290836 | Q10: 9.21B | S10: Liquidity Cost Table | U10: Formula: a + b×ln(x)
A11: QQQM | B11: Invesco NASDAQ 100 ETF | C11: 247.32 | D11: 72.81B | E11: 0.0015 | F11: 1.21 | G11: =IF(RIGHT(Q11,1)="B", VALUE(SUBSTITUTE(Q11,"B",""))*1000000000, IF(RIGHT(Q11,1)="M", VALUE(SUBSTITUTE(Q11,"M",""))*1000000, VALUE(Q11))) -> 1260000000 | H11: =OR( ISNUMBER(SEARCH("technology",B11)), ISNUMBER(SEARCH("tech",B11)), ISNUMBER(SEARCH("qqq",B11)), ISNUMBER(SEARCH("semiconductor",B11)), ISNUMBER(SEARCH("information technology",B11)), ISNUMBER(SEARCH("nasdaq",B11)), ISNUMBER(SEARCH("communication",B11)) ) -> TRUE | I11: =Table1[[#This Row],[Tech]]*$T$7+Table1[[#This Row],[Beta]]*($T$6-$T$8)+$T$8 -> 0.213356 | J11: 3.2610723e+08 | K11: =Table1[[#This Row],[Investment]]/Table1[[#This Row],[Dollar Volume]] -> 0.25881526 | L11: =IFERROR(MAX($T$11+$T$12*LN(Table1[[#This Row],[Frac ADV]]),0),0)*0.0001+0.005/Table1[[#This Row],[Stock Price]]+Table1[[#This Row],[Expense Ratio]] -> 0.026155946 | M11: =(Table1[[#This Row],[Expected Return]]-Table1[[#This Row],[Tcosts]])*Table1[[#This Row],[Investment]] -> 61047290 | Q11: 1.26B | S11: a | T11: 312.56344
A12: XLC | B12: State Street Communication Services Select Sector SPDR ETF | C12: 114.64 | D12: 26.69B | E12: 0.0008 | F12: 0.94 | G12: =IF(RIGHT(Q12,1)="B", VALUE(SUBSTITUTE(Q12,"B",""))*1000000000, IF(RIGHT(Q12,1)="M", VALUE(SUBSTITUTE(Q12,"M",""))*1000000, VALUE(Q12))) -> 736290000 | H12: =OR( ISNUMBER(SEARCH("technology",B12)), ISNUMBER(SEARCH("tech",B12)), ISNUMBER(SEARCH("qqq",B12)), ISNUMBER(SEARCH("semiconductor",B12)), ISNUMBER(SEARCH("information technology",B12)), ISNUMBER(SEARCH("nasdaq",B12)), ISNUMBER(SEARCH("communication",B12)) ) -> TRUE | I12: =Table1[[#This Row],[Tech]]*$T$7+Table1[[#This Row],[Beta]]*($T$6-$T$8)+$T$8 -> 0.196184 | J12: 2.9347674e+08 | K12: =Table1[[#This Row],[Investment]]/Table1[[#This Row],[Dollar Volume]] -> 0.39858852 | L12: =IFERROR(MAX($T$11+$T$12*LN(Table1[[#This Row],[Frac ADV]]),0),0)*0.0001+0.005/Table1[[#This Row],[Stock Price]]+Table1[[#This Row],[Expense Ratio]] -> 0.027594463 | M12: =(Table1[[#This Row],[Expected Return]]-Table1[[#This Row],[Tcosts]])*Table1[[#This Row],[Investment]] -> 49477108 | Q12: 736.29M | S12: b | T12: 48.982056
A13: JEPQ | B13: JPMorgan NASDAQ Equity Premium Income ETF | C13: 57.44 | D13: 34.13B | E13: 0.0035 | F13: 0.95 | G13: =IF(RIGHT(Q13,1)="B", VALUE(SUBSTITUTE(Q13,"B",""))*1000000000, IF(RIGHT(Q13,1)="M", VALUE(SUBSTITUTE(Q13,"M",""))*1000000, VALUE(Q13))) -> 1780000000 | H13: =OR( ISNUMBER(SEARCH("technology",B13)), ISNUMBER(SEARCH("tech",B13)), ISNUMBER(SEARCH("qqq",B13)), ISNUMBER(SEARCH("semiconductor",B13)), ISNUMBER(SEARCH("information technology",B13)), ISNUMBER(SEARCH("nasdaq",B13)), ISNUMBER(SEARCH("communication",B13)) ) -> TRUE | I13: =Table1[[#This Row],[Tech]]*$T$7+Table1[[#This Row],[Beta]]*($T$6-$T$8)+$T$8 -> 0.19682 | J13: 2.8403578e+08 | K13: =Table1[[#This Row],[Investment]]/Table1[[#This Row],[Dollar Volume]] -> 0.15957066 | L13: =IFERROR(MAX($T$11+$T$12*LN(Table1[[#This Row],[Frac ADV]]),0),0)*0.0001+0.005/Table1[[#This Row],[Stock Price]]+Table1[[#This Row],[Expense Ratio]] -> 0.025853869 | M13: =(Table1[[#This Row],[Expected Return]]-Table1[[#This Row],[Tcosts]])*Table1[[#This Row],[Investment]] -> 48560498 | Q13: 1.78B
A14: IUSG | B14: iShares Core S&P U.S. Growth ETF | C14: 163.69 | D14: 27.40B | E14: 0.0004 | F14: 1.19 | G14: =IF(RIGHT(Q14,1)="B", VALUE(SUBSTITUTE(Q14,"B",""))*1000000000, IF(RIGHT(Q14,1)="M", VALUE(SUBSTITUTE(Q14,"M",""))*1000000, VALUE(Q14))) -> 1120000000 | H14: =OR( ISNUMBER(SEARCH("technology",B14)), ISNUMBER(SEARCH("tech",B14)), ISNUMBER(SEARCH("qqq",B14)), ISNUMBER(SEARCH("semiconductor",B14)), ISNUMBER(SEARCH("information technology",B14)), ISNUMBER(SEARCH("nasdaq",B14)), ISNUMBER(SEARCH("communication",B14)) ) -> FALSE | I14: =Table1[[#This Row],[Tech]]*$T$7+Table1[[#This Row],[Beta]]*($T$6-$T$8)+$T$8 -> 0.112084 | J14: 1.1954905e+08 | K14: =Table1[[#This Row],[Investment]]/Table1[[#This Row],[Dollar Volume]] -> 0.10674022 | L14: =IFERROR(MAX($T$11+$T$12*LN(Table1[[#This Row],[Frac ADV]]),0),0)*0.0001+0.005/Table1[[#This Row],[Stock Price]]+Table1[[#This Row],[Expense Ratio]] -> 0.020727854 | M14: =(Table1[[#This Row],[Expected Return]]-Table1[[#This Row],[Tcosts]])*Table1[[#This Row],[Investment]] -> 10921540 | Q14: 1.12B
A15: VOOG | B15: Vanguard S&P 500 Growth ETF | C15: 430.93 | D15: 22.28B | E15: 0.0007 | F15: 1.21 | G15: =IF(RIGHT(Q15,1)="B", VALUE(SUBSTITUTE(Q15,"B",""))*1000000000, IF(RIGHT(Q15,1)="M", VALUE(SUBSTITUTE(Q15,"M",""))*1000000, VALUE(Q15))) -> 978550000 | H15: =OR( ISNUMBER(SEARCH("technology",B15)), ISNUMBER(SEARCH("tech",B15)), ISNUMBER(SEARCH("qqq",B15)), ISNUMBER(SEARCH("semiconductor",B15)), ISNUMBER(SEARCH("information technology",B15)), ISNUMBER(SEARCH("nasdaq",B15)), ISNUMBER(SEARCH("communication",B15)) ) -> FALSE | I15: =Table1[[#This Row],[Tech]]*$T$7+Table1[[#This Row],[Beta]]*($T$6-$T$8)+$T$8 -> 0.113356 | J15: 1.1173582e+08 | K15: =Table1[[#This Row],[Investment]]/Table1[[#This Row],[Dollar Volume]] -> 0.11418509 | L15: =IFERROR(MAX($T$11+$T$12*LN(Table1[[#This Row],[Frac ADV]]),0),0)*0.0001+0.005/Table1[[#This Row],[Stock Price]]+Table1[[#This Row],[Expense Ratio]] -> 0.021339161 | M15: =(Table1[[#This Row],[Expected Return]]-Table1[[#This Row],[Tcosts]])*Table1[[#This Row],[Investment]] -> 10281577 | Q15: 978.55M | S15: Gross Profit | T15: =SUM(Table1[Exp Profit]) -> 1.3819722e+09
A16: SCHG | B16: Schwab U.S. Large-Cap Growth ETF | C16: 30.51 | D16: 51.58B | E16: 0.0004 | F16: 1.24 | G16: =IF(RIGHT(Q16,1)="B", VALUE(SUBSTITUTE(Q16,"B",""))*1000000000, IF(RIGHT(Q16,1)="M", VALUE(SUBSTITUTE(Q16,"M",""))*1000000, VALUE(Q16))) -> 968150000 | H16: =OR( ISNUMBER(SEARCH("technology",B16)), ISNUMBER(SEARCH("tech",B16)), ISNUMBER(SEARCH("qqq",B16)), ISNUMBER(SEARCH("semiconductor",B16)), ISNUMBER(SEARCH("information technology",B16)), ISNUMBER(SEARCH("nasdaq",B16)), ISNUMBER(SEARCH("communication",B16)) ) -> FALSE | I16: =Table1[[#This Row],[Tech]]*$T$7+Table1[[#This Row],[Beta]]*($T$6-$T$8)+$T$8 -> 0.115264 | J16: 86560304 | K16: =Table1[[#This Row],[Investment]]/Table1[[#This Row],[Dollar Volume]] -> 0.089407947 | L16: =IFERROR(MAX($T$11+$T$12*LN(Table1[[#This Row],[Frac ADV]]),0),0)*0.0001+0.005/Table1[[#This Row],[Stock Price]]+Table1[[#This Row],[Expense Ratio]] -> 0.019993283 | M16: =(Table1[[#This Row],[Expected Return]]-Table1[[#This Row],[Tcosts]])*Table1[[#This Row],[Investment]] -> 8246662.2 | Q16: 968.15M | S16: Total Investment | T16: =SUM(Table1[Investment]) -> 9.2680685e+09
A17: IWY | B17: iShares Russell Top 200 Growth ETF | C17: 262.27 | D17: 15.85B | E17: 0.002 | F17: 1.2 | G17: =IF(RIGHT(Q17,1)="B", VALUE(SUBSTITUTE(Q17,"B",""))*1000000000, IF(RIGHT(Q17,1)="M", VALUE(SUBSTITUTE(Q17,"M",""))*1000000, VALUE(Q17))) -> 582850000 | H17: =OR( ISNUMBER(SEARCH("technology",B17)), ISNUMBER(SEARCH("tech",B17)), ISNUMBER(SEARCH("qqq",B17)), ISNUMBER(SEARCH("semiconductor",B17)), ISNUMBER(SEARCH("information technology",B17)), ISNUMBER(SEARCH("nasdaq",B17)), ISNUMBER(SEARCH("communication",B17)) ) -> FALSE | I17: =Table1[[#This Row],[Tech]]*$T$7+Table1[[#This Row],[Beta]]*($T$6-$T$8)+$T$8 -> 0.11272 | J17: 77548749 | K17: =Table1[[#This Row],[Investment]]/Table1[[#This Row],[Dollar Volume]] -> 0.13305095 | L17: =IFERROR(MAX($T$11+$T$12*LN(Table1[[#This Row],[Frac ADV]]),0),0)*0.0001+0.005/Table1[[#This Row],[Stock Price]]+Table1[[#This Row],[Expense Ratio]] -> 0.023395614 | M17: =(Table1[[#This Row],[Expected Return]]-Table1[[#This Row],[Tcosts]])*Table1[[#This Row],[Investment]] -> 6926994.3 | Q17: 582.85M | S17: Margin Interest | T17: =MAX((T16-T5),0)*T9 -> 4.6631906e+08
A18: IWF | B18: iShares Russell 1000 Growth ETF | C18: 448.96 | D18: 118.84B | E18: 0.0018 | F18: 1.22 | G18: =IF(RIGHT(Q18,1)="B", VALUE(SUBSTITUTE(Q18,"B",""))*1000000000, IF(RIGHT(Q18,1)="M", VALUE(SUBSTITUTE(Q18,"M",""))*1000000, VALUE(Q18))) -> 469470000 | H18: =OR( ISNUMBER(SEARCH("technology",B18)), ISNUMBER(SEARCH("tech",B18)), ISNUMBER(SEARCH("qqq",B18)), ISNUMBER(SEARCH("semiconductor",B18)), ISNUMBER(SEARCH("information technology",B18)), ISNUMBER(SEARCH("nasdaq",B18)), ISNUMBER(SEARCH("communication",B18)) ) -> FALSE | I18: =Table1[[#This Row],[Tech]]*$T$7+Table1[[#This Row],[Beta]]*($T$6-$T$8)+$T$8 -> 0.113992 | J18: 76710043 | K18: =Table1[[#This Row],[Investment]]/Table1[[#This Row],[Dollar Volume]] -> 0.16339711 | L18: =IFERROR(MAX($T$11+$T$12*LN(Table1[[#This Row],[Frac ADV]]),0),0)*0.0001+0.005/Table1[[#This Row],[Stock Price]]+Table1[[#This Row],[Expense Ratio]] -> 0.02419403 | M18: =(Table1[[#This Row],[Expected Return]]-Table1[[#This Row],[Tcosts]])*Table1[[#This Row],[Investment]] -> 6888406.1 | Q18: 469.47M | S18: Net Profit | T18: =T15-T17 -> 9.1565317e+08
A19: VB | B19: Vanguard Small-Cap ETF | C19: 272.94 | D19: 74.53B | E19: 0.0003 | F19: 0.94 | G19: =IF(RIGHT(Q19,1)="B", VALUE(SUBSTITUTE(Q19,"B",""))*1000000000, IF(RIGHT(Q19,1)="M", VALUE(SUBSTITUTE(Q19,"M",""))*1000000, VALUE(Q19))) -> 1870000000 | H19: =OR( ISNUMBER(SEARCH("technology",B19)), ISNUMBER(SEARCH("tech",B19)), ISNUMBER(SEARCH("qqq",B19)), ISNUMBER(SEARCH("semiconductor",B19)), ISNUMBER(SEARCH("information technology",B19)), ISNUMBER(SEARCH("nasdaq",B19)), ISNUMBER(SEARCH("communication",B19)) ) -> FALSE | I19: =Table1[[#This Row],[Tech]]*$T$7+Table1[[#This Row],[Beta]]*($T$6-$T$8)+$T$8 -> 0.096184 | J19: 75911711 | K19: =Table1[[#This Row],[Investment]]/Table1[[#This Row],[Dollar Volume]] -> 0.040594498 | L19: =IFERROR(MAX($T$11+$T$12*LN(Table1[[#This Row],[Frac ADV]]),0),0)*0.0001+0.005/Table1[[#This Row],[Stock Price]]+Table1[[#This Row],[Expense Ratio]] -> 0.015880211 | M19: =(Table1[[#This Row],[Expected Return]]-Table1[[#This Row],[Tcosts]])*Table1[[#This Row],[Investment]] -> 6095998 | Q19: 1.87B | S19: Num Positions | T19: =COUNTIF(Table1[Investment],">0") -> 192
A20: SPMO | B20: Invesco S&P 500 Momentum ETF | C20: 118.27 | D20: 13.58B | E20: 0.0013 | F20: 1.23 | G20: =IF(RIGHT(Q20,1)="B", VALUE(SUBSTITUTE(Q20,"B",""))*1000000000, IF(RIGHT(Q20,1)="M", VALUE(SUBSTITUTE(Q20,"M",""))*1000000, VALUE(Q20))) -> 1.07e+09 | H20: =OR( ISNUMBER(SEARCH("technology",B20)), ISNUMBER(SEARCH("tech",B20)), ISNUMBER(SEARCH("qqq",B20)), ISNUMBER(SEARCH("semiconductor",B20)), ISNUMBER(SEARCH("information technology",B20)), ISNUMBER(SEARCH("nasdaq",B20)), ISNUMBER(SEARCH("communication",B20)) ) -> FALSE | I20: =Table1[[#This Row],[Tech]]*$T$7+Table1[[#This Row],[Beta]]*($T$6-$T$8)+$T$8 -> 0.114628 | J20: 75905495 | K20: =Table1[[#This Row],[Investment]]/Table1[[#This Row],[Dollar Volume]] -> 0.070939715 | L20: =IFERROR(MAX($T$11+$T$12*LN(Table1[[#This Row],[Frac ADV]]),0),0)*0.0001+0.005/Table1[[#This Row],[Stock Price]]+Table1[[#This Row],[Expense Ratio]] -> 0.019638336 | M20: =(Table1[[#This Row],[Expected Return]]-Table1[[#This Row],[Tcosts]])*Table1[[#This Row],[Investment]] -> 7210237.4 | Q20: 1.07B | S20: Final Portfolio Value | T20: =T18+T5 -> 1.9156532e+09
A21: CGGR | B21: Capital Group Growth ETF | C21: 42.54 | D21: 19.92B | E21: 0.0039 | F21: 1.22 | G21: =IF(RIGHT(Q21,1)="B", VALUE(SUBSTITUTE(Q21,"B",""))*1000000000, IF(RIGHT(Q21,1)="M", VALUE(SUBSTITUTE(Q21,"M",""))*1000000, VALUE(Q21))) -> 456530000 | H21: =OR( ISNUMBER(SEARCH("technology",B21)), ISNUMBER(SEARCH("tech",B21)), ISNUMBER(SEARCH("qqq",B21)), ISNUMBER(SEARCH("semiconductor",B21)), ISNUMBER(SEARCH("information technology",B21)), ISNUMBER(SEARCH("nasdaq",B21)), ISNUMBER(SEARCH("communication",B21)) ) -> FALSE | I21: =Table1[[#This Row],[Tech]]*$T$7+Table1[[#This Row],[Beta]]*($T$6-$T$8)+$T$8 -> 0.113992 | J21: 74924000 | K21: =Table1[[#This Row],[Investment]]/Table1[[#This Row],[Dollar Volume]] -> 0.16411627 | L21: =IFERROR(MAX($T$11+$T$12*LN(Table1[[#This Row],[Frac ADV]]),0),0)*0.0001+0.005/Table1[[#This Row],[Stock Price]]+Table1[[#This Row],[Expense Ratio]] -> 0.02642194 | M21: =(Table1[[#This Row],[Expected Return]]-Table1[[#This Row],[Tcosts]])*Table1[[#This Row],[Investment]] -> 6561099.2 | Q21: 456.53M | S21: Return on Equity | T21: =T18/T5 -> 0.91565317
A22: SPSM | B22: State Street SPDR Portfolio S&P 600 Small Cap ETF | C22: 50.4 | D22: 14.76B | E22: 0.0003 | F22: 0.92 | G22: =IF(RIGHT(Q22,1)="B", VALUE(SUBSTITUTE(Q22,"B",""))*1000000000, IF(RIGHT(Q22,1)="M", VALUE(SUBSTITUTE(Q22,"M",""))*1000000, VALUE(Q22))) -> 1220000000 | H22: =OR( ISNUMBER(SEARCH("technology",B22)), ISNUMBER(SEARCH("tech",B22)), ISNUMBER(SEARCH("qqq",B22)), ISNUMBER(SEARCH("semiconductor",B22)), ISNUMBER(SEARCH("information technology",B22)), ISNUMBER(SEARCH("nasdaq",B22)), ISNUMBER(SEARCH("communication",B22)) ) -> FALSE | I22: =Table1[[#This Row],[Tech]]*$T$7+Table1[[#This Row],[Beta]]*($T$6-$T$8)+$T$8 -> 0.094912 | J22: 74827167 | K22: =Table1[[#This Row],[Investment]]/Table1[[#This Row],[Dollar Volume]] -> 0.061333743 | L22: =IFERROR(MAX($T$11+$T$12*LN(Table1[[#This Row],[Frac ADV]]),0),0)*0.0001+0.005/Table1[[#This Row],[Stock Price]]+Table1[[#This Row],[Expense Ratio]] -> 0.017982576 | M22: =(Table1[[#This Row],[Expected Return]]-Table1[[#This Row],[Tcosts]])*Table1[[#This Row],[Investment]] -> 5756410.8 | Q22: 1.22B
A23: MGK | B23: Vanguard Mega Cap Growth ETF | C23: 386.83 | D23: 30.78B | E23: 0.0005 | F23: 1.27 | G23: =IF(RIGHT(Q23,1)="B", VALUE(SUBSTITUTE(Q23,"B",""))*1000000000, IF(RIGHT(Q23,1)="M", VALUE(SUBSTITUTE(Q23,"M",""))*1000000, VALUE(Q23))) -> 309820000 | H23: =OR( ISNUMBER(SEARCH("technology",B23)), ISNUMBER(SEARCH("tech",B23)), ISNUMBER(SEARCH("qqq",B23)), ISNUMBER(SEARCH("semiconductor",B23)), ISNUMBER(SEARCH("information technology",B23)), ISNUMBER(SEARCH("nasdaq",B23)), ISNUMBER(SEARCH("communication",B23)) ) -> FALSE | I23: =Table1[[#This Row],[Tech]]*$T$7+Table1[[#This Row],[Beta]]*($T$6-$T$8)+$T$8 -> 0.117172 | J23: 74653057 | K23: =Table1[[#This Row],[Investment]]/Table1[[#This Row],[Dollar Volume]] -> 0.24095622 | L23: =IFERROR(MAX($T$11+$T$12*LN(Table1[[#This Row],[Frac ADV]]),0),0)*0.0001+0.005/Table1[[#This Row],[Stock Price]]+Table1[[#This Row],[Expense Ratio]] -> 0.024798437 | M23: =(Table1[[#This Row],[Expected Return]]-Table1[[#This Row],[Tcosts]])*Table1[[#This Row],[Investment]] -> 6895968.9 | Q23: 309.82M
A24: SPYG | B24: State Street SPDR Portfolio S&P 500 Growth ETF | C24: 103.45 | D24: 45.15B | E24: 0.0004 | F24: 1.21 | G24: =IF(RIGHT(Q24,1)="B", VALUE(SUBSTITUTE(Q24,"B",""))*1000000000, IF(RIGHT(Q24,1)="M", VALUE(SUBSTITUTE(Q24,"M",""))*1000000, VALUE(Q24))) -> 4470000000 | H24: =OR( ISNUMBER(SEARCH("technology",B24)), ISNUMBER(SEARCH("tech",B24)), ISNUMBER(SEARCH("qqq",B24)), ISNUMBER(SEARCH("semiconductor",B24)), ISNUMBER(SEARCH("information technology",B24)), ISNUMBER(SEARCH("nasdaq",B24)), ISNUMBER(SEARCH("communication",B24)) ) -> FALSE | I24: =Table1[[#This Row],[Tech]]*$T$7+Table1[[#This Row],[Beta]]*($T$6-$T$8)+$T$8 -> 0.113356 | J24: 73728349 | K24: =Table1[[#This Row],[Investment]]/Table1[[#This Row],[Dollar Volume]] -> 0.016494038 | L24: =IFERROR(MAX($T$11+$T$12*LN(Table1[[#This Row],[Frac ADV]]),0),0)*0.0001+0.005/Table1[[#This Row],[Stock Price]]+Table1[[#This Row],[Expense Ratio]] -> 0.011598736 | M24: =(Table1[[#This Row],[Expected Return]]-Table1[[#This Row],[Tcosts]])*Table1[[#This Row],[Investment]] -> 7502395.1 | Q24: 4.47B
A25: OEF | B25: iShares S&P 100 ETF | C25: 335.05 | D25: 29.12B | E25: 0.002 | F25: 1.08 | G25: =IF(RIGHT(Q25,1)="B", VALUE(SUBSTITUTE(Q25,"B",""))*1000000000, IF(RIGHT(Q25,1)="M", VALUE(SUBSTITUTE(Q25,"M",""))*1000000, VALUE(Q25))) -> 7750000000 | H25: =OR( ISNUMBER(SEARCH("technology",B25)), ISNUMBER(SEARCH("tech",B25)), ISNUMBER(SEARCH("qqq",B25)), ISNUMBER(SEARCH("semiconductor",B25)), ISNUMBER(SEARCH("information technology",B25)), ISNUMBER(SEARCH("nasdaq",B25)), ISNUMBER(SEARCH("communication",B25)) ) -> FALSE | I25: =Table1[[#This Row],[Tech]]*$T$7+Table1[[#This Row],[Beta]]*($T$6-$T$8)+$T$8 -> 0.105088 | J25: 73619087 | K25: =Table1[[#This Row],[Investment]]/Table1[[#This Row],[Dollar Volume]] -> 0.0094992371 | L25: =IFERROR(MAX($T$11+$T$12*LN(Table1[[#This Row],[Frac ADV]]),0),0)*0.0001+0.005/Table1[[#This Row],[Stock Price]]+Table1[[#This Row],[Expense Ratio]] -> 0.010462558 | M25: =(Table1[[#This Row],[Expected Return]]-Table1[[#This Row],[Tcosts]])*Table1[[#This Row],[Investment]] -> 6966238.7 | Q25: 7.75B
A26: VUG | B26: Vanguard Growth ETF | C26: 460.15 | D26: 200.60B | E26: 0.0003 | F26: 1.24 | G26: =IF(RIGHT(Q26,1)="B", VALUE(SUBSTITUTE(Q26,"B",""))*1000000000, IF(RIGHT(Q26,1)="M", VALUE(SUBSTITUTE(Q26,"M",""))*1000000, VALUE(Q26))) -> 722110000 | H26: =OR( ISNUMBER(SEARCH("technology",B26)), ISNUMBER(SEARCH("tech",B26)), ISNUMBER(SEARCH("qqq",B26)), ISNUMBER(SEARCH("semiconductor",B26)), ISNUMBER(SEARCH("information technology",B26)), ISNUMBER(SEARCH("nasdaq",B26)), ISNUMBER(SEARCH("communication",B26)) ) -> FALSE | I26: =Table1[[#This Row],[Tech]]*$T$7+Table1[[#This Row],[Beta]]*($T$6-$T$8)+$T$8 -> 0.115264 | J26: 73468986 | K26: =Table1[[#This Row],[Investment]]/Table1[[#This Row],[Dollar Volume]] -> 0.1017421 | L26: =IFERROR(MAX($T$11+$T$12*LN(Table1[[#This Row],[Frac ADV]]),0),0)*0.0001+0.005/Table1[[#This Row],[Stock Price]]+Table1[[#This Row],[Expense Ratio]] -> 0.020373271 | M26: =(Table1[[#This Row],[Expected Return]]-Table1[[#This Row],[Tcosts]])*Table1[[#This Row],[Investment]] -> 6971525.6 | Q26: 722.11M
A27: IVW | B27: iShares S&P 500 Growth ETF | C27: 119.49 | D27: 65.70B | E27: 0.0018 | F27: 1.21 | G27: =IF(RIGHT(Q27,1)="B", VALUE(SUBSTITUTE(Q27,"B",""))*1000000000, IF(RIGHT(Q27,1)="M", VALUE(SUBSTITUTE(Q27,"M",""))*1000000, VALUE(Q27))) -> 1290000000 | H27: =OR( ISNUMBER(SEARCH("technology",B27)), ISNUMBER(SEARCH("tech",B27)), ISNUMBER(SEARCH("qqq",B27)), ISNUMBER(SEARCH("semiconductor",B27)), ISNUMBER(SEARCH("information technology",B27)), ISNUMBER(SEARCH("nasdaq",B27)), ISNUMBER(SEARCH("communication",B27)) ) -> FALSE | I27: =Table1[[#This Row],[Tech]]*$T$7+Table1[[#This Row],[Beta]]*($T$6-$T$8)+$T$8 -> 0.113356 | J27: 72849381 | K27: =Table1[[#This Row],[Investment]]/Table1[[#This Row],[Dollar Volume]] -> 0.056472389 | L27: =IFERROR(MAX($T$11+$T$12*LN(Table1[[#This Row],[Frac ADV]]),0),0)*0.0001+0.005/Table1[[#This Row],[Stock Price]]+Table1[[#This Row],[Expense Ratio]] -> 0.019020729 | M27: =(Table1[[#This Row],[Expected Return]]-Table1[[#This Row],[Tcosts]])*Table1[[#This Row],[Investment]] -> 6872266.2 | Q27: 1.29B
A28: VONG | B28: Vanguard Russell 1000 Growth ETF | C28: 115.5 | D28: 37.92B | E28: 0.0006 | F28: 1.22 | G28: =IF(RIGHT(Q28,1)="B", VALUE(SUBSTITUTE(Q28,"B",""))*1000000000, IF(RIGHT(Q28,1)="M", VALUE(SUBSTITUTE(Q28,"M",""))*1000000, VALUE(Q28))) -> 2080000000 | H28: =OR( ISNUMBER(SEARCH("technology",B28)), ISNUMBER(SEARCH("tech",B28)), ISNUMBER(SEARCH("qqq",B28)), ISNUMBER(SEARCH("semiconductor",B28)), ISNUMBER(SEARCH("information technology",B28)), ISNUMBER(SEARCH("nasdaq",B28)), ISNUMBER(SEARCH("communication",B28)) ) -> FALSE | I28: =Table1[[#This Row],[Tech]]*$T$7+Table1[[#This Row],[Beta]]*($T$6-$T$8)+$T$8 -> 0.113992 | J28: 71772100 | K28: =Table1[[#This Row],[Investment]]/Table1[[#This Row],[Dollar Volume]] -> 0.034505817 | L28: =IFERROR(MAX($T$11+$T$12*LN(Table1[[#This Row],[Frac ADV]]),0),0)*0.0001+0.005/Table1[[#This Row],[Stock Price]]+Table1[[#This Row],[Expense Ratio]] -> 0.015409201 | M28: =(Table1[[#This Row],[Expected Return]]-Table1[[#This Row],[Tcosts]])*Table1[[#This Row],[Investment]] -> 7075494.5 | Q28: 2.08B
A29: SCHA | B29: Schwab U.S. Small-Cap ETF | C29: 30.31 | D29: 20.87B | E29: 0.0004 | F29: 0.98 | G29: =IF(RIGHT(Q29,1)="B", VALUE(SUBSTITUTE(Q29,"B",""))*1000000000, IF(RIGHT(Q29,1)="M", VALUE(SUBSTITUTE(Q29,"M",""))*1000000, VALUE(Q29))) -> 12250000000 | H29: =OR( ISNUMBER(SEARCH("technology",B29)), ISNUMBER(SEARCH("tech",B29)), ISNUMBER(SEARCH("qqq",B29)), ISNUMBER(SEARCH("semiconductor",B29)), ISNUMBER(SEARCH("information technology",B29)), ISNUMBER(SEARCH("nasdaq",B29)), ISNUMBER(SEARCH("communication",B29)) ) -> FALSE | I29: =Table1[[#This Row],[Tech]]*$T$7+Table1[[#This Row],[Beta]]*($T$6-$T$8)+$T$8 -> 0.098728 | J29: 65239254 | K29: =Table1[[#This Row],[Investment]]/Table1[[#This Row],[Dollar Volume]] -> 0.0053256534 | L29: =IFERROR(MAX($T$11+$T$12*LN(Table1[[#This Row],[Frac ADV]]),0),0)*0.0001+0.005/Table1[[#This Row],[Stock Price]]+Table1[[#This Row],[Expense Ratio]] -> 0.0061781227 | M29: =(Table1[[#This Row],[Expected Return]]-Table1[[#This Row],[Tcosts]])*Table1[[#This Row],[Investment]] -> 6037885 | Q29: 12.25B
A30: VXF | B30: Vanguard Extended Market ETF | C30: 213.85 | D30: 26.36B | E30: 0.0005 | F30: 1.07 | G30: =IF(RIGHT(Q30,1)="B", VALUE(SUBSTITUTE(Q30,"B",""))*1000000000, IF(RIGHT(Q30,1)="M", VALUE(SUBSTITUTE(Q30,"M",""))*1000000, VALUE(Q30))) -> 3070000000 | H30: =OR( ISNUMBER(SEARCH("technology",B30)), ISNUMBER(SEARCH("tech",B30)), ISNUMBER(SEARCH("qqq",B30)), ISNUMBER(SEARCH("semiconductor",B30)), ISNUMBER(SEARCH("information technology",B30)), ISNUMBER(SEARCH("nasdaq",B30)), ISNUMBER(SEARCH("communication",B30)) ) -> FALSE | I30: =Table1[[#This Row],[Tech]]*$T$7+Table1[[#This Row],[Beta]]*($T$6-$T$8)+$T$8 -> 0.104452 | J30: 64885376 | K30: =Table1[[#This Row],[Investment]]/Table1[[#This Row],[Dollar Volume]] -> 0.021135302 | L30: =IFERROR(MAX($T$11+$T$12*LN(Table1[[#This Row],[Frac ADV]]),0),0)*0.0001+0.005/Table1[[#This Row],[Stock Price]]+Table1[[#This Row],[Expense Ratio]] -> 0.012888274 | M30: =(Table1[[#This Row],[Expected Return]]-Table1[[#This Row],[Tcosts]])*Table1[[#This Row],[Investment]] -> 5941146.8 | Q30: 3.07B
A31: SCHB | B31: Schwab U.S. Broad Market ETF | C31: 26.29 | D31: 39.10B | E31: 0.0003 | F31: 1 | G31: =IF(RIGHT(Q31,1)="B", VALUE(SUBSTITUTE(Q31,"B",""))*1000000000, IF(RIGHT(Q31,1)="M", VALUE(SUBSTITUTE(Q31,"M",""))*1000000, VALUE(Q31))) -> 236140000 | H31: =OR( ISNUMBER(SEARCH("technology",B31)), ISNUMBER(SEARCH("tech",B31)), ISNUMBER(SEARCH("qqq",B31)), ISNUMBER(SEARCH("semiconductor",B31)), ISNUMBER(SEARCH("information technology",B31)), ISNUMBER(SEARCH("nasdaq",B31)), ISNUMBER(SEARCH("communication",B31)) ) -> FALSE | I31: =Table1[[#This Row],[Tech]]*$T$7+Table1[[#This Row],[Beta]]*($T$6-$T$8)+$T$8 -> 0.1 | J31: 63530415 | K31: =Table1[[#This Row],[Investment]]/Table1[[#This Row],[Dollar Volume]] -> 0.26903707 | L31: =IFERROR(MAX($T$11+$T$12*LN(Table1[[#This Row],[Frac ADV]]),0),0)*0.0001+0.005/Table1[[#This Row],[Stock Price]]+Table1[[#This Row],[Expense Ratio]] -> 0.025315646 | M31: =(Table1[[#This Row],[Expected Return]]-Table1[[#This Row],[Tcosts]])*Table1[[#This Row],[Investment]] -> 4744728 | Q31: 236.14M
A32: VBK | B32: Vanguard Small-Cap Growth ETF | C32: 310.33 | D32: 21.33B | E32: 0.0005 | F32: 1.06 | G32: =IF(RIGHT(Q32,1)="B", VALUE(SUBSTITUTE(Q32,"B",""))*1000000000, IF(RIGHT(Q32,1)="M", VALUE(SUBSTITUTE(Q32,"M",""))*1000000, VALUE(Q32))) -> 341000000 | H32: =OR( ISNUMBER(SEARCH("technology",B32)), ISNUMBER(SEARCH("tech",B32)), ISNUMBER(SEARCH("qqq",B32)), ISNUMBER(SEARCH("semiconductor",B32)), ISNUMBER(SEARCH("information technology",B32)), ISNUMBER(SEARCH("nasdaq",B32)), ISNUMBER(SEARCH("communication",B32)) ) -> FALSE | I32: =Table1[[#This Row],[Tech]]*$T$7+Table1[[#This Row],[Beta]]*($T$6-$T$8)+$T$8 -> 0.103816 | J32: 61922186 | K32: =Table1[[#This Row],[Investment]]/Table1[[#This Row],[Dollar Volume]] -> 0.18158999 | L32: =IFERROR(MAX($T$11+$T$12*LN(Table1[[#This Row],[Frac ADV]]),0),0)*0.0001+0.005/Table1[[#This Row],[Stock Price]]+Table1[[#This Row],[Expense Ratio]] -> 0.023416098 | M32: =(Table1[[#This Row],[Expected Return]]-Table1[[#This Row],[Tcosts]])*Table1[[#This Row],[Investment]] -> 4978537.7 | Q32: 341.00M
A33: IWP | B33: iShares Russell Mid-Cap Growth ETF | C33: 132.91 | D33: 20.00B | E33: 0.0023 | F33: 1.13 | G33: =IF(RIGHT(Q33,1)="B", VALUE(SUBSTITUTE(Q33,"B",""))*1000000000, IF(RIGHT(Q33,1)="M", VALUE(SUBSTITUTE(Q33,"M",""))*1000000, VALUE(Q33))) -> 434610000 | H33: =OR( ISNUMBER(SEARCH("technology",B33)), ISNUMBER(SEARCH("tech",B33)), ISNUMBER(SEARCH("qqq",B33)), ISNUMBER(SEARCH("semiconductor",B33)), ISNUMBER(SEARCH("information technology",B33)), ISNUMBER(SEARCH("nasdaq",B33)), ISNUMBER(SEARCH("communication",B33)) ) -> FALSE | I33: =Table1[[#This Row],[Tech]]*$T$7+Table1[[#This Row],[Beta]]*($T$6-$T$8)+$T$8 -> 0.108268 | J33: 61753573 | K33: =Table1[[#This Row],[Investment]]/Table1[[#This Row],[Dollar Volume]] -> 0.14208963 | L33: =IFERROR(MAX($T$11+$T$12*LN(Table1[[#This Row],[Frac ADV]]),0),0)*0.0001+0.005/Table1[[#This Row],[Stock Price]]+Table1[[#This Row],[Expense Ratio]] -> 0.024036108 | M33: =(Table1[[#This Row],[Expected Return]]-Table1[[#This Row],[Tcosts]])*Table1[[#This Row],[Investment]] -> 5201620.3 | Q33: 434.61M
... A201: MBB | B201: iShares MBS ETF | C201: 96.14 | D201: 39.28B | E201: 0.0004 | F201: -0.05 | G201: =IF(RIGHT(Q201,1)="B", VALUE(SUBSTITUTE(Q201,"B",""))*1000000000, IF(RIGHT(Q201,1)="M", VALUE(SUBSTITUTE(Q201,"M",""))*1000000, VALUE(Q201))) -> 24620000 | H201: =OR( ISNUMBER(SEARCH("technology",B201)), ISNUMBER(SEARCH("tech",B201)), ISNUMBER(SEARCH("qqq",B201)), ISNUMBER(SEARCH("semiconductor",B201)), ISNUMBER(SEARCH("information technology",B201)), ISNUMBER(SEARCH("nasdaq",B201)), ISNUMBER(SEARCH("communication",B201)) ) -> FALSE | I201: =Table1[[#This Row],[Tech]]*$T$7+Table1[[#This Row],[Beta]]*($T$6-$T$8)+$T$8 -> 0.03322 | J201: 0 | K201: =Table1[[#This Row],[Investment]]/Table1[[#This Row],[Dollar Volume]] -> 0 | L201: =IFERROR(MAX($T$11+$T$12*LN(Table1[[#This Row],[Frac ADV]]),0),0)*0.0001+0.005/Table1[[#This Row],[Stock Price]]+Table1[[#This Row],[Expense Ratio]] -> 0.00045200749 | M201: =(Table1[[#This Row],[Expected Return]]-Table1[[#This Row],[Tcosts]])*Table1[[#This Row],[Investment]] -> 0 | Q201: 24.62M

Sheet Model A UB (Revolutionary)
A1: Symbol | B1: Fund Name | C1: Stock Price | D1: AUM | E1: Expense Ratio | F1: Beta | G1: Dollar Volume | H1: Tech | I1: Expected Return | J1: Investment | K1: Frac ADV | L1: Tcosts | M1: Exp Profit | Q1: Just for Reference | S1: Part 2: Model Setup — Key Assumptions
A2: SOXL | B2: Direxion Daily Semiconductor Bull 3x Shares | C2: 63.1 | D2: 13.17B | E2: 0.0075 | F2: =4.99/3 -> 1.6633333 | G2: =IF(RIGHT(Q2,1)="B", VALUE(SUBSTITUTE(Q2,"B",""))*1000000000, IF(RIGHT(Q2,1)="M", VALUE(SUBSTITUTE(Q2,"M",""))*1000000, VALUE(Q2))) -> 5570000000 | H2: =OR( ISNUMBER(SEARCH("technology",B2)), ISNUMBER(SEARCH("tech",B2)), ISNUMBER(SEARCH("qqq",B2)), ISNUMBER(SEARCH("semiconductor",B2)), ISNUMBER(SEARCH("information technology",B2)), ISNUMBER(SEARCH("nasdaq",B2)), ISNUMBER(SEARCH("communication",B2)) ) -> TRUE | I2: =Table14[[#This Row],[Tech]]*$T$7+Table14[[#This Row],[Beta]]*($T$6-$T$8)+$T$8 -> 0.242188 | J2: 9.9996661e+09 | K2: =Table14[[#This Row],[Investment]]/Table14[[#This Row],[Dollar Volume]] -> 1.7952722 | L2: =IFERROR(MAX($T$11+$T$12*LN(Table14[[#This Row],[Frac ADV]]),0),0)*0.0001+0.005/Table14[[#This Row],[Stock Price]]+Table14[[#This Row],[Expense Ratio]] -> 0.041701801 | M2: =(Table14[[#This Row],[Expected Return]]-Table14[[#This Row],[Tcosts]])*Table14[[#This Row],[Investment]] -> 2.004795e+09 | Q2: 5.57B
A3: FTEC | B3: Fidelity MSCI Information Technology Index ETF | C3: 217.72 | D3: 16.24B | E3: 0.0008 | F3: 1.43 | G3: =IF(RIGHT(Q3,1)="B", VALUE(SUBSTITUTE(Q3,"B",""))*1000000000, IF(RIGHT(Q3,1)="M", VALUE(SUBSTITUTE(Q3,"M",""))*1000000, VALUE(Q3))) -> 5500000000 | H3: =OR( ISNUMBER(SEARCH("technology",B3)), ISNUMBER(SEARCH("tech",B3)), ISNUMBER(SEARCH("qqq",B3)), ISNUMBER(SEARCH("semiconductor",B3)), ISNUMBER(SEARCH("information technology",B3)), ISNUMBER(SEARCH("nasdaq",B3)), ISNUMBER(SEARCH("communication",B3)) ) -> TRUE | I3: =Table14[[#This Row],[Tech]]*$T$7+Table14[[#This Row],[Beta]]*($T$6-$T$8)+$T$8 -> 0.227348 | J3: 9.9995824e+09 | K3: =Table14[[#This Row],[Investment]]/Table14[[#This Row],[Dollar Volume]] -> 1.8181059 | L3: =IFERROR(MAX($T$11+$T$12*LN(Table14[[#This Row],[Frac ADV]]),0),0)*0.0001+0.005/Table14[[#This Row],[Stock Price]]+Table14[[#This Row],[Expense Ratio]] -> 0.035007433 | M3: =(Table14[[#This Row],[Expected Return]]-Table14[[#This Row],[Tcosts]])*Table14[[#This Row],[Investment]] -> 1.9233254e+09 | Q3: 5.50B | S3: Assumptions
A4: VGT | B4: Vanguard Information Technology ETF | C4: 729.64 | D4: 113.34B | E4: 0.0009 | F4: 1.43 | G4: =IF(RIGHT(Q4,1)="B", VALUE(SUBSTITUTE(Q4,"B",""))*1000000000, IF(RIGHT(Q4,1)="M", VALUE(SUBSTITUTE(Q4,"M",""))*1000000, VALUE(Q4))) -> 79900000000 | H4: =OR( ISNUMBER(SEARCH("technology",B4)), ISNUMBER(SEARCH("tech",B4)), ISNUMBER(SEARCH("qqq",B4)), ISNUMBER(SEARCH("semiconductor",B4)), ISNUMBER(SEARCH("information technology",B4)), ISNUMBER(SEARCH("nasdaq",B4)), ISNUMBER(SEARCH("communication",B4)) ) -> TRUE | I4: =Table14[[#This Row],[Tech]]*$T$7+Table14[[#This Row],[Beta]]*($T$6-$T$8)+$T$8 -> 0.227348 | J4: 9.9993881e+09 | K4: =Table14[[#This Row],[Investment]]/Table14[[#This Row],[Dollar Volume]] -> 0.12514879 | L4: =IFERROR(MAX($T$11+$T$12*LN(Table14[[#This Row],[Frac ADV]]),0),0)*0.0001+0.005/Table14[[#This Row],[Stock Price]]+Table14[[#This Row],[Expense Ratio]] -> 0.021983491 | M4: =(Table14[[#This Row],[Expected Return]]-Table14[[#This Row],[Tcosts]])*Table14[[#This Row],[Investment]] -> 2.0535194e+09 | Q4: 79.90B | S4: Parameter | T4: Value | U4: Notes
A5: SOXX | B5: iShares Semiconductor ETF | C5: 351.5 | D5: 22.09B | E5: 0.0034 | F5: 1.74 | G5: =IF(RIGHT(Q5,1)="B", VALUE(SUBSTITUTE(Q5,"B",""))*1000000000, IF(RIGHT(Q5,1)="M", VALUE(SUBSTITUTE(Q5,"M",""))*1000000, VALUE(Q5))) -> 2350000000 | H5: =OR( ISNUMBER(SEARCH("technology",B5)), ISNUMBER(SEARCH("tech",B5)), ISNUMBER(SEARCH("qqq",B5)), ISNUMBER(SEARCH("semiconductor",B5)), ISNUMBER(SEARCH("information technology",B5)), ISNUMBER(SEARCH("nasdaq",B5)), ISNUMBER(SEARCH("communication",B5)) ) -> TRUE | I5: =Table14[[#This Row],[Tech]]*$T$7+Table14[[#This Row],[Beta]]*($T$6-$T$8)+$T$8 -> 0.247064 | J5: 9.9992721e+09 | K5: =Table14[[#This Row],[Investment]]/Table14[[#This Row],[Dollar Volume]] -> 4.2550094 | L5: =IFERROR(MAX($T$11+$T$12*LN(Table14[[#This Row],[Frac ADV]]),0),0)*0.0001+0.005/Table14[[#This Row],[Stock Price]]+Table14[[#This Row],[Expense Ratio]] -> 0.041763645 | M5: =(Table14[[#This Row],[Expected Return]]-Table14[[#This Row],[Tcosts]])*Table14[[#This Row],[Investment]] -> 2.0528541e+09 | Q5: 2.35B | S5: Starting Capital | T5: 1000000000 | U5: Fund equity
A6: TQQQ | B6: ProShares UltraPro QQQ | C6: 48.26 | D6: 28.70B | E6: 0.0082 | F6: 3.58 | G6: =IF(RIGHT(Q6,1)="B", VALUE(SUBSTITUTE(Q6,"B",""))*1000000000, IF(RIGHT(Q6,1)="M", VALUE(SUBSTITUTE(Q6,"M",""))*1000000, VALUE(Q6))) -> 48350000000 | H6: =OR( ISNUMBER(SEARCH("technology",B6)), ISNUMBER(SEARCH("tech",B6)), ISNUMBER(SEARCH("qqq",B6)), ISNUMBER(SEARCH("semiconductor",B6)), ISNUMBER(SEARCH("information technology",B6)), ISNUMBER(SEARCH("nasdaq",B6)), ISNUMBER(SEARCH("communication",B6)) ) -> TRUE | I6: =Table14[[#This Row],[Tech]]*$T$7+Table14[[#This Row],[Beta]]*($T$6-$T$8)+$T$8 -> 0.364088 | J6: 9.9990037e+09 | K6: =Table14[[#This Row],[Investment]]/Table14[[#This Row],[Dollar Volume]] -> 0.20680463 | L6: =IFERROR(MAX($T$11+$T$12*LN(Table14[[#This Row],[Frac ADV]]),0),0)*0.0001+0.005/Table14[[#This Row],[Stock Price]]+Table14[[#This Row],[Expense Ratio]] -> 0.031840472 | M6: =(Table14[[#This Row],[Expected Return]]-Table14[[#This Row],[Tcosts]])*Table14[[#This Row],[Investment]] -> 3.3221443e+09 | Q6: 48.35B | S6: Market Return | T6: 0.1 | U6: Expected S&P 500 gain (annual)
A7: JEPQ | B7: JPMorgan NASDAQ Equity Premium Income ETF | C7: 57.44 | D7: 34.13B | E7: 0.0035 | F7: 0.95 | G7: =IF(RIGHT(Q7,1)="B", VALUE(SUBSTITUTE(Q7,"B",""))*1000000000, IF(RIGHT(Q7,1)="M", VALUE(SUBSTITUTE(Q7,"M",""))*1000000, VALUE(Q7))) -> 1360000000 | H7: =OR( ISNUMBER(SEARCH("technology",B7)), ISNUMBER(SEARCH("tech",B7)), ISNUMBER(SEARCH("qqq",B7)), ISNUMBER(SEARCH("semiconductor",B7)), ISNUMBER(SEARCH("information technology",B7)), ISNUMBER(SEARCH("nasdaq",B7)), ISNUMBER(SEARCH("communication",B7)) ) -> TRUE | I7: =Table14[[#This Row],[Tech]]*$T$7+Table14[[#This Row],[Beta]]*($T$6-$T$8)+$T$8 -> 0.19682 | J7: 9.9983832e+09 | K7: =Table14[[#This Row],[Investment]]/Table14[[#This Row],[Dollar Volume]] -> 7.3517524 | L7: =IFERROR(MAX($T$11+$T$12*LN(Table14[[#This Row],[Frac ADV]]),0),0)*0.0001+0.005/Table14[[#This Row],[Stock Price]]+Table14[[#This Row],[Expense Ratio]] -> 0.044615011 | M7: =(Table14[[#This Row],[Expected Return]]-Table14[[#This Row],[Tcosts]])*Table14[[#This Row],[Investment]] -> 1.5218038e+09 | Q7: 1.36B | S7: Tech Alpha | T7: 0.1 | U7: Additional annual return for tech ETFs
A8: QQQM | B8: Invesco NASDAQ 100 ETF | C8: 247.32 | D8: 72.81B | E8: 0.0015 | F8: 1.21 | G8: =IF(RIGHT(Q8,1)="B", VALUE(SUBSTITUTE(Q8,"B",""))*1000000000, IF(RIGHT(Q8,1)="M", VALUE(SUBSTITUTE(Q8,"M",""))*1000000, VALUE(Q8))) -> 1020000000 | H8: =OR( ISNUMBER(SEARCH("technology",B8)), ISNUMBER(SEARCH("tech",B8)), ISNUMBER(SEARCH("qqq",B8)), ISNUMBER(SEARCH("semiconductor",B8)), ISNUMBER(SEARCH("information technology",B8)), ISNUMBER(SEARCH("nasdaq",B8)), ISNUMBER(SEARCH("communication",B8)) ) -> TRUE | I8: =Table14[[#This Row],[Tech]]*$T$7+Table14[[#This Row],[Beta]]*($T$6-$T$8)+$T$8 -> 0.213356 | J8: 9.9983528e+09 | K8: =Table14[[#This Row],[Investment]]/Table14[[#This Row],[Dollar Volume]] -> 9.8023066 | L8: =IFERROR(MAX($T$11+$T$12*LN(Table14[[#This Row],[Frac ADV]]),0),0)*0.0001+0.005/Table14[[#This Row],[Stock Price]]+Table14[[#This Row],[Expense Ratio]] -> 0.043957292 | M8: =(Table14[[#This Row],[Expected Return]]-Table14[[#This Row],[Tcosts]])*Table14[[#This Row],[Investment]] -> 1.693708e+09 | Q8: 1.02B | S8: Fed Funds Rate | T8: 0.0364 | U8: Look up current rate at Federal Reserve | V8: 46076
A9: SMH | B9: VanEck Semiconductor ETF | C9: 406.11 | D9: 45.17B | E9: 0.0035 | F9: 1.71 | G9: =IF(RIGHT(Q9,1)="B", VALUE(SUBSTITUTE(Q9,"B",""))*1000000000, IF(RIGHT(Q9,1)="M", VALUE(SUBSTITUTE(Q9,"M",""))*1000000, VALUE(Q9))) -> 1800000000 | H9: =OR( ISNUMBER(SEARCH("technology",B9)), ISNUMBER(SEARCH("tech",B9)), ISNUMBER(SEARCH("qqq",B9)), ISNUMBER(SEARCH("semiconductor",B9)), ISNUMBER(SEARCH("information technology",B9)), ISNUMBER(SEARCH("nasdaq",B9)), ISNUMBER(SEARCH("communication",B9)) ) -> TRUE | I9: =Table14[[#This Row],[Tech]]*$T$7+Table14[[#This Row],[Beta]]*($T$6-$T$8)+$T$8 -> 0.245156 | J9: 9.9982112e+09 | K9: =Table14[[#This Row],[Investment]]/Table14[[#This Row],[Dollar Volume]] -> 5.5545618 | L9: =IFERROR(MAX($T$11+$T$12*LN(Table14[[#This Row],[Frac ADV]]),0),0)*0.0001+0.005/Table14[[#This Row],[Stock Price]]+Table14[[#This Row],[Expense Ratio]] -> 0.043167215 | M9: =(Table14[[#This Row],[Expected Return]]-Table14[[#This Row],[Tcosts]])*Table14[[#This Row],[Investment]] -> 2.0195265e+09 | Q9: 1.80B | S9: Margin Interest Rate | T9: =T8+2% -> 0.0564 | U9: Annual cost of borrowing
A10: XLK | B10: State Street Technology Select Sector SPDR ETF | C10: 139.21 | D10: 90.52B | E10: 0.0008 | F10: 1.41 | G10: =IF(RIGHT(Q10,1)="B", VALUE(SUBSTITUTE(Q10,"B",""))*1000000000, IF(RIGHT(Q10,1)="M", VALUE(SUBSTITUTE(Q10,"M",""))*1000000, VALUE(Q10))) -> 9210000000 | H10: =OR( ISNUMBER(SEARCH("technology",B10)), ISNUMBER(SEARCH("tech",B10)), ISNUMBER(SEARCH("qqq",B10)), ISNUMBER(SEARCH("semiconductor",B10)), ISNUMBER(SEARCH("information technology",B10)), ISNUMBER(SEARCH("nasdaq",B10)), ISNUMBER(SEARCH("communication",B10)) ) -> TRUE | I10: =Table14[[#This Row],[Tech]]*$T$7+Table14[[#This Row],[Beta]]*($T$6-$T$8)+$T$8 -> 0.226076 | J10: 9.9981108e+09 | K10: =Table14[[#This Row],[Investment]]/Table14[[#This Row],[Dollar Volume]] -> 1.0855712 | L10: =IFERROR(MAX($T$11+$T$12*LN(Table14[[#This Row],[Frac ADV]]),0),0)*0.0001+0.005/Table14[[#This Row],[Stock Price]]+Table14[[#This Row],[Expense Ratio]] -> 0.032494434 | M10: =(Table14[[#This Row],[Expected Return]]-Table14[[#This Row],[Tcosts]])*Table14[[#This Row],[Investment]] -> 1.9354499e+09 | Q10: 9.21B | S10: Liquidity Cost Table | U10: Formula: a + b×ln(x)
A11: XLC | B11: State Street Communication Services Select Sector SPDR ETF | C11: 114.64 | D11: 26.69B | E11: 0.0008 | F11: 0.94 | G11: =IF(RIGHT(Q11,1)="B", VALUE(SUBSTITUTE(Q11,"B",""))*1000000000, IF(RIGHT(Q11,1)="M", VALUE(SUBSTITUTE(Q11,"M",""))*1000000, VALUE(Q11))) -> 1260000000 | H11: =OR( ISNUMBER(SEARCH("technology",B11)), ISNUMBER(SEARCH("tech",B11)), ISNUMBER(SEARCH("qqq",B11)), ISNUMBER(SEARCH("semiconductor",B11)), ISNUMBER(SEARCH("information technology",B11)), ISNUMBER(SEARCH("nasdaq",B11)), ISNUMBER(SEARCH("communication",B11)) ) -> TRUE | I11: =Table14[[#This Row],[Tech]]*$T$7+Table14[[#This Row],[Beta]]*($T$6-$T$8)+$T$8 -> 0.196184 | J11: 9.9980067e+09 | K11: =Table14[[#This Row],[Investment]]/Table14[[#This Row],[Dollar Volume]] -> 7.934926 | L11: =IFERROR(MAX($T$11+$T$12*LN(Table14[[#This Row],[Frac ADV]]),0),0)*0.0001+0.005/Table14[[#This Row],[Stock Price]]+Table14[[#This Row],[Expense Ratio]] -> 0.042245485 | M11: =(Table14[[#This Row],[Expected Return]]-Table14[[#This Row],[Tcosts]])*Table14[[#This Row],[Investment]] -> 1.5390783e+09 | Q11: 1.26B | S11: a | T11: 312.56344
A12: IYW | B12: iShares U.S. Technology ETF | C12: 190.79 | D12: 20.42B | E12: 0.0038 | F12: 1.43 | G12: =IF(RIGHT(Q12,1)="B", VALUE(SUBSTITUTE(Q12,"B",""))*1000000000, IF(RIGHT(Q12,1)="M", VALUE(SUBSTITUTE(Q12,"M",""))*1000000, VALUE(Q12))) -> 736290000 | H12: =OR( ISNUMBER(SEARCH("technology",B12)), ISNUMBER(SEARCH("tech",B12)), ISNUMBER(SEARCH("qqq",B12)), ISNUMBER(SEARCH("semiconductor",B12)), ISNUMBER(SEARCH("information technology",B12)), ISNUMBER(SEARCH("nasdaq",B12)), ISNUMBER(SEARCH("communication",B12)) ) -> TRUE | I12: =Table14[[#This Row],[Tech]]*$T$7+Table14[[#This Row],[Beta]]*($T$6-$T$8)+$T$8 -> 0.227348 | J12: 9.9968738e+09 | K12: =Table14[[#This Row],[Investment]]/Table14[[#This Row],[Dollar Volume]] -> 13.577359 | L12: =IFERROR(MAX($T$11+$T$12*LN(Table14[[#This Row],[Frac ADV]]),0),0)*0.0001+0.005/Table14[[#This Row],[Stock Price]]+Table14[[#This Row],[Expense Ratio]] -> 0.047859048 | M12: =(Table14[[#This Row],[Expected Return]]-Table14[[#This Row],[Tcosts]])*Table14[[#This Row],[Investment]] -> 1.7943284e+09 | Q12: 736.29M | S12: b | T12: 48.982056
A13: VOOG | B13: Vanguard S&P 500 Growth ETF | C13: 430.93 | D13: 22.28B | E13: 0.0007 | F13: 1.21 | G13: =IF(RIGHT(Q13,1)="B", VALUE(SUBSTITUTE(Q13,"B",""))*1000000000, IF(RIGHT(Q13,1)="M", VALUE(SUBSTITUTE(Q13,"M",""))*1000000, VALUE(Q13))) -> 1780000000 | H13: =OR( ISNUMBER(SEARCH("technology",B13)), ISNUMBER(SEARCH("tech",B13)), ISNUMBER(SEARCH("qqq",B13)), ISNUMBER(SEARCH("semiconductor",B13)), ISNUMBER(SEARCH("information technology",B13)), ISNUMBER(SEARCH("nasdaq",B13)), ISNUMBER(SEARCH("communication",B13)) ) -> FALSE | I13: =Table14[[#This Row],[Tech]]*$T$7+Table14[[#This Row],[Beta]]*($T$6-$T$8)+$T$8 -> 0.113356 | J13: 9.9950012e+09 | K13: =Table14[[#This Row],[Investment]]/Table14[[#This Row],[Dollar Volume]] -> 5.6151692 | L13: =IFERROR(MAX($T$11+$T$12*LN(Table14[[#This Row],[Frac ADV]]),0),0)*0.0001+0.005/Table14[[#This Row],[Stock Price]]+Table14[[#This Row],[Expense Ratio]] -> 0.040419662 | M13: =(Table14[[#This Row],[Expected Return]]-Table14[[#This Row],[Tcosts]])*Table14[[#This Row],[Investment]] -> 7.2899879e+08 | Q13: 1.78B
A14: QQQ | B14: Invesco QQQ Trust Series I | C14: 600.64 | D14: 402.60B | E14: 0.002 | F14: 1.22 | G14: =IF(RIGHT(Q14,1)="B", VALUE(SUBSTITUTE(Q14,"B",""))*1000000000, IF(RIGHT(Q14,1)="M", VALUE(SUBSTITUTE(Q14,"M",""))*1000000, VALUE(Q14))) -> 1120000000 | H14: =OR( ISNUMBER(SEARCH("technology",B14)), ISNUMBER(SEARCH("tech",B14)), ISNUMBER(SEARCH("qqq",B14)), ISNUMBER(SEARCH("semiconductor",B14)), ISNUMBER(SEARCH("information technology",B14)), ISNUMBER(SEARCH("nasdaq",B14)), ISNUMBER(SEARCH("communication",B14)) ) -> TRUE | I14: =Table14[[#This Row],[Tech]]*$T$7+Table14[[#This Row],[Beta]]*($T$6-$T$8)+$T$8 -> 0.213992 | J14: 9.9941959e+09 | K14: =Table14[[#This Row],[Investment]]/Table14[[#This Row],[Dollar Volume]] -> 8.9233892 | L14: =IFERROR(MAX($T$11+$T$12*LN(Table14[[#This Row],[Frac ADV]]),0),0)*0.0001+0.005/Table14[[#This Row],[Stock Price]]+Table14[[#This Row],[Expense Ratio]] -> 0.043985253 | M14: =(Table14[[#This Row],[Expected Return]]-Table14[[#This Row],[Tcosts]])*Table14[[#This Row],[Investment]] -> 1.6990807e+09 | Q14: 1.12B
A15: IUSG | B15: iShares Core S&P U.S. Growth ETF | C15: 163.69 | D15: 27.40B | E15: 0.0004 | F15: 1.19 | G15: =IF(RIGHT(Q15,1)="B", VALUE(SUBSTITUTE(Q15,"B",""))*1000000000, IF(RIGHT(Q15,1)="M", VALUE(SUBSTITUTE(Q15,"M",""))*1000000, VALUE(Q15))) -> 978550000 | H15: =OR( ISNUMBER(SEARCH("technology",B15)), ISNUMBER(SEARCH("tech",B15)), ISNUMBER(SEARCH("qqq",B15)), ISNUMBER(SEARCH("semiconductor",B15)), ISNUMBER(SEARCH("information technology",B15)), ISNUMBER(SEARCH("nasdaq",B15)), ISNUMBER(SEARCH("communication",B15)) ) -> FALSE | I15: =Table14[[#This Row],[Tech]]*$T$7+Table14[[#This Row],[Beta]]*($T$6-$T$8)+$T$8 -> 0.112084 | J15: 9.9755868e+09 | K15: =Table14[[#This Row],[Investment]]/Table14[[#This Row],[Dollar Volume]] -> 10.194254 | L15: =IFERROR(MAX($T$11+$T$12*LN(Table14[[#This Row],[Frac ADV]]),0),0)*0.0001+0.005/Table14[[#This Row],[Stock Price]]+Table14[[#This Row],[Expense Ratio]] -> 0.043059662 | M15: =(Table14[[#This Row],[Expected Return]]-Table14[[#This Row],[Tcosts]])*Table14[[#This Row],[Investment]] -> 6.8855828e+08 | Q15: 978.55M | S15: Gross Profit | T15: =SUM(Table14[Exp Profit]) -> 3.2492266e+10
